Workbook

Sheet Cover
B2: LATCHED
B3: Financial Model — v1.0
B4: Last Updated: June 2026
B6: Lactation Support App · Early Stage · Confidential
B9: NAVIGATION
B10: → Assumptions | C10: All hardcoded inputs — edit here first
B11: → Revenue | C11: Monthly revenue build, 18-month horizon
B12: → COGS | C12: Variable cost per user (Stripe, LLM, infra)
B13: → OpEx | C13: Fixed & semi-fixed monthly operating expenses
B14: → P&L | C14: Monthly P&L summary
B15: → Unit Economics | C15: LTV · CAC · Payback · Gross Margin
B16: → Missing Inputs | C16: Priority list of figures Ashley must gather
B18: COLOR KEY
B19: Blue text = Hardcoded input (change for scenarios)
B20: Black text = Formula / calculated value
B21: Green text = Link from another sheet
B22: Red text = External link / source
B23: Yellow bg = Placeholder — figure needed
B26: HOW TO READ THIS MODEL
B27: Start with the Assumption Register tab. It lists every judgment call, its source, and how much to trust it.
B29: 1. SCOPE
B30: Latched covers a 15-MONTH infant feeding journey with four evidence-based engagement peaks (see Journey Map tab):
B31: 1) Milk establishment (wks 0-8) 2) Return to work (M3-4) 3) Solids introduction (M5-7) 4) Weaning (M12-15)
B33: 2. TWO SEPARATE BUSINESS MODELS — DO NOT MIX THEM
... B44: 4. COLOUR LEGEND
B45: BLUE text | C45: means: an input you can change
B46: BLACK text | C46: means: a calculated formula. Do not overwrite.
B47: YELLOW fill | C47: means: a key lever worth stress-testing
B48: Hover a cell | C48: means: high-impact inputs carry a pop-up comment with source and rationale
B50: 5. THE HONEST CAVEATS
B51: - Founder salary is $0. Profitability here is PRE-founder-compensation.
B52: - Six inputs are PLACEHOLDERS (see Register): willingness-to-pay, referral conversion, partners/month,
B53: referrals per partner, sponsor engagement, contract renewal. These carry most of the risk.
B54: - Market size is not the constraint. Every scenario captures <0.3% of the served market (see TAM).
B55: The binding constraint is ACQUISITION, which is why the model is built around the referral channel.
B57: 6. TAB ORDER
B58: Assumption Register -> Assumptions -> GrowthEngine -> Revenue -> COGS -> OpEx -> P&L -> Scenarios -> TAM -> Payer Model -> Unit Economics -> Missing Inputs -> Change Log

Sheet Assumption Register
B1: ASSUMPTION REGISTER — AUDIT TRAIL
B2: Every judgment call in this model, with source and confidence. Values are LIVE-LINKED to the model — they cannot drift out of sync.
B3: READ FIRST: sort by Confidence. PLACEHOLDER = a guess carrying real risk. SOURCED = hard data.
B5: ID | C5: Cell | D5: Assumption | E5: Value (live) | F5: Confidence | G5: Impact if wrong | H5: Source | I5: Rationale / why this number | J5: Validation status
B6: A-01 | C6: Assumptions!C4 | D6: One-time app price | E6: =Assumptions!C4 -> 49 | F6: Benchmarked | G6: HIGH | H6: PRD v0.9; competitor scan | I6: $49. Priced for the original 6-week scope. The 12-month milk-to-solids scope likely supports $69-99 — see Unit Economics price sensitivity. | J6: Needs WTP test
B7: A-02 | C7: Assumptions!C6 | D7: Refund rate | E7: =Assumptions!C6 -> 0.1 | F7: Benchmarked | G7: MED | H7: PRD v0.9 (target <10%) | I7: 10% used as a conservative ceiling rather than the target. | J7: Validate post-launch
B8: A-03 | C8: Assumptions!C10 | D8: Stripe % fee | E8: =Assumptions!C10 -> 0.029 | F8: Sourced | G8: LOW | H8: Stripe published pricing | I8: 2.9% standard US card rate. | J8: Validated
B9: A-04 | C9: Assumptions!C14 | D9: B2C CAC | E9: =Assumptions!C14 -> 30 | F9: Benchmarked | G9: HIGH | H9: PRD v0.9; Meta/IG CPA benchmarks | I9: $30. At $49 this yields only 1.41x LTV:CAC — the paid B2C channel is structurally thin. This finding drove the pivot to referral. | J9: Needs live test
B10: A-05 | C10: Assumptions!C16 | D10: B2B2C CAC | E10: =Assumptions!C16 -> 10 | F10: Estimated | G10: HIGH | H10: Referral partner economics | I10: $10. Warm referral is ~3x cheaper than paid, producing 4.24x LTV:CAC. This is why the growth engine is referral-based. | J10: Needs live test
B11: A-06 | C11: Assumptions!C18 | D11: Referrals per IBCLC / month | E11: =Assumptions!C18 -> 3 | F11: Placeholder | G11: HIGH | H11: Founder estimate | I11: 3/month. UNVALIDATED and a core driver of all B2B2C volume. | J11: MUST VALIDATE
B12: A-07 | C12: Assumptions!C79 | D12: New IBCLC partners / month | E12: =Assumptions!C79 -> 5 | F12: Placeholder | G12: HIGH | H12: Founder estimate | I12: 5/month. THE growth lever — scenarios flex 3/5/8. Nearly all revenue variance traces back here. | J12: MUST VALIDATE
B13: A-08 | C13: Assumptions!C81 | D13: Referral to paid conversion | E13: =Assumptions!C81 -> 0.5 | F13: Placeholder | G13: HIGH | H13: Founder estimate | I13: 50%. A warm handoff from a trusted IBCLC should convert well, but this is unproven. | J13: MUST VALIDATE
B14: A-09 | C14: Assumptions!C31 | D14: Active weeks per user (15-mo) | E14: =Assumptions!C31 -> 32 | F14: Estimated | G14: LOW | H14: CDC NIS-Child 2022; Journey Map tab | I14: 32 active weeks across a ~65-wk journey. Sum of four evidence-based peaks: establishment (9), return-to-work (7), solids (9), weaning (7). Peak TIMING is CDC data; the active-week counts are estimates. | J14: Validate in beta
B15: A-10 | C15: Assumptions!C30 | D15: Queries per active week | E15: =Assumptions!C30 -> 4 | F15: Estimated | G15: LOW | H15: UX spec (2-5 range) | I15: 4/week. Low impact — LLM cost is trivial on Haiku. | J15: Validate in beta
B16: A-11 | C16: Assumptions!C74 | D16: Founder salary | E16: =Assumptions!C74 -> 0 | F16: Estimated | G16: HIGH | H16: Founder decision — bootstrap | I16: $0. The model EXCLUDES founder opportunity cost. Profitability here is pre-founder-comp — a reader must know this. | J16: Deliberate
B17: A-12 | C17: Assumptions!C70 | D17: Paid marketing / month | E17: =Assumptions!C70 -> 750 | F17: Estimated | G17: MED | H17: Founder decision | I17: $750/mo post-launch. Flat spend against a growing base means implied CAC drifts down over time; acceptable at v1 scale. | J17: Revisit at scale
B18: A-13 | C18: Assumptions!C66 | D18: Advisor hours / month | E18: =Assumptions!C66 -> 6 | F18: Estimated | G18: MED | H18: Founder estimate | I18: 6 hrs x $75 = $450/mo. Single biggest driver pushing breakeven from M9 to M12. | J18: Confirm w/ advisor
B19: A-14 | C19: Assumptions!C61 | D19: Advisor hourly rate | E19: =Assumptions!C61 -> 75 | F19: Sourced | G19: MED | H19: ACTION-ITEMS.md ($75-150 range) | I19: $75/hr — low end of the documented range. | J19: Validated
B20: A-15 | C20: Assumptions!C41 | D20: Supabase Pro | E20: =Assumptions!C41 -> 25 | F20: Sourced | G20: LOW | H20: technical-design-v1.md; Supabase pricing | I20: $25/mo. | J20: Validated
B21: A-16 | C21: Assumptions!C32 | D21: Haiku input token cost | E21: =Assumptions!C32 -> 0.00025 | F21: Sourced | G21: LOW | H21: Anthropic published pricing | I21: Public rate card. | J21: Validated
B22: A-17 | C22: TAM!C5 | D22: US births / year | E22: =TAM!C5 -> 3628934 | F22: Sourced | G22: HIGH | H22: CDC/NCHS, Births in the US 2024 (final) | I22: 3,628,934 registered births. Hard national data. | J22: Validated
B23: A-18 | C23: TAM!C6 | D23: Breastfeeding initiation | E23: =TAM!C6 -> 0.83 | F23: Sourced | G23: HIGH | H23: CDC NIS-Child (birth yr 2022) | I23: ~83% ever breastfed. National blend of subgroups (82.4% ages 20-29; 87.5% age 30+; 92.2% WIC-ineligible). | J23: Validated
B24: A-19 | C24: TAM!C8 | D24: Digital-reachable share | E24: =TAM!C8 -> 0.9 | F24: Estimated | G24: MED | H24: Assumption | I24: 90%. Smartphone use among new mothers is near-universal. | J24: Low risk
B25: A-20 | C25: TAM!C9 | D25: Willingness to pay | E25: =TAM!C9 -> 0.3 | F25: Placeholder | G25: HIGH | H25: PLACEHOLDER | I25: 30%. The single largest swing in SAM. Held at 30% by decision, pending the WTP study. | J25: MUST VALIDATE
B26: A-21 | C26: Payer Model!C15 | D26: Sponsor engagement rate | E26: ='Payer Model'!C15 -> 0.45 | F26: Placeholder | G26: HIGH | H26: Founder estimate | I26: 45% of a covered birth cohort activates. Drives all per-member sponsor revenue. | J26: MUST VALIDATE
B27: A-22 | C27: Payer Model!C17 | D27: Contract renewal rate | E27: ='Payer Model'!C17 -> 0.85 | F27: Placeholder | G27: HIGH | H27: Enterprise SaaS norm | I27: 85% implies a 6.7-yr expected contract life. Biggest swing in contract LTV. No evidence behind it yet. | J27: MUST VALIDATE
B28: A-23 | C28: Payer Model!C16 | D28: Platform fee / contract | E28: ='Payer Model'!C16 -> 25000 | F28: Benchmarked | G28: MED | H28: Maven (Sacra): $20-40K/yr | I28: $25K — mid-range of the public benchmark. | J28: Benchmark only
B29: A-24 | C29: Payer Model!C14 | D29: Births per contract | E29: ='Payer Model'!C14 -> 800 | F29: Estimated | G29: MED | H29: Mid-size employer/plan | I29: 800/yr. Sizing assumption for a mid-size sponsor. | J29: Per-deal input
B30: A-25 | C30: Journey Map!C22 | D30: Median weaning age | E30: ='Journey Map'!C22 -> 0 | F30: Sourced | G30: HIGH | H30: CDC NIS-Child 2022 (n=19,309) | I30: 50.7% of 6-week survivors still breastfeeding at 12 months — median weaning is ~12 months. This is WHY scope extends to 15 months: a 12-month product would end exactly at the median weaning event. | J30: Validated
B31: A-26 | C31: Journey Map!E16 | D31: Solids weaning cliff | E31: ='Journey Map'!E16 -> 0.129 | F31: Sourced | G31: HIGH | H31: CDC NIS-Child 2022 | I31: 12.9% of remaining mothers stop between month 6 and 7 — the single biggest monthly cliff in year one. Strongest evidence for the solids module. | J31: Validated
B32: A-27 | C32: Journey Map!E13 | D32: Return-to-work cliff | E32: ='Journey Map'!E13 -> 0.077 | F32: Sourced | G32: MED | H32: CDC NIS-Child 2022 | I32: 7.7% hazard at M3-M4, coinciding with the end of ~12-week US maternity leave. Basis for adding return-to-work as peak 2. | J32: Validated
B33: Sourced | C33: Hard external data or a published rate card. Trust it.
B34: Benchmarked | C34: Anchored to a real external comparable, but not our own data.
B35: Estimated | C35: Reasoned founder judgment. Directionally sound, unproven.
B36: Placeholder | C36: A guess. Carries real risk. Validate before relying on it.

Sheet Assumptions
B1: LATCHED — ASSUMPTIONS | C1: Low / Base | D1: Confidence | E1: Source & rationale (audit trail)
B3: PRICING & REVENUE
B4: One-time app price | C4: 49 | D4: Benchmarked | E4: [PRD v0.9; competitor scan (LactApp, Nest)] $49 one-time. NOTE: priced for 6-wk scope; 12-mo milk→solids scope may justify $69–99 (see Unit Economics price sensitivity).
B5: Money-back guarantee window (days) | C5: 30 | E5: Source: mvp-experience-spec v1.0
B6: Target refund rate | C6: 0.1 | D6: Benchmarked | E6: [PRD v0.9 — target <10%] 10% refund used as conservative ceiling, not target.
B7: B2B2C attribution share (% of signups) | C7: 0.4 | E7: Source: PRD v0.9 — target ≥40% via IBCLC referral channel
B9: PAYMENT PROCESSING (STRIPE)
B10: Stripe percentage fee | C10: 0.029 | D10: Sourced | E10: [Stripe published pricing] 2.9% + $0.30 standard US card rate.
B11: Stripe per-transaction fee ($) | C11: 0.3 | D11: Sourced | E11: [Stripe published pricing] Fixed per-transaction fee.
B13: CUSTOMER ACQUISITION
B14: B2C blended CAC target ($) | C14: 30 | D14: Benchmarked | E14: [PRD v0.9; Meta/IG CPA benchmarks] $30 blended B2C CAC target. At $49 price this yields only 1.41x LTV:CAC — structurally thin.
B15: B2C CAC high scenario ($) | C15: 65 | E15: [Filled] conservative / high scenario CAC
B16: B2B2C CAC — estimated ($) | C16: 10 | D16: Estimated | E16: [Referral partner economics] $10 B2B2C CAC — warm referral is far cheaper than paid. Drives the 4.24x LTV:CAC that justifies the referral strategy.
B17: IBCLC design partners recruited (#) | C17: 7 | D17: Estimated | E17: [ACTION-ITEMS.md target 5-10] 7 design partners at launch.
B18: Avg moms referred per IBCLC per month | C18: 3 | D18: Placeholder | E18: [Founder estimate] 3 referrals per IBCLC per month. UNVALIDATED — core driver of the entire growth engine.
B19: B2C paid conversion rate (landing page → purchase) | C19: 0.02 | D19: Placeholder | E19: [Industry landing-page norms] 2% B2C conversion. Informational only — not wired to signups (spend÷CAC drives B2C).
B21: USER GROWTH ASSUMPTIONS
B22: Launch month (Month #) | C22: 5 | E22: Source: 4-5 month build timeline per conversation-summary-2026-05-24. Model uses Month 5.
B23: New paid signups — Month 5 (launch) | C23: 10 | E23: Source: ~100 signups in first 90 days target (PRD). Assume ramp: 10→30→60 across months 5-7.
B24: New paid signups — Month 6 | C24: 30 | E24: Source: derived from 100-in-90-days target (PRD v0.9)
B25: New paid signups — Month 7 | C25: 60 | E25: Source: derived from 100-in-90-days target (PRD v0.9)
B26: Monthly growth rate post-Month 7 (%) | C26: 0.15 | E26: [Filled] organic + paid growth assumption post-100 users
B27: Churn rate (% of total users/month) | C27: 0 | E27: One-time purchase — no subscription churn. Set 0. Track re-engage.
B29: LLM & API COSTS
B30: Smart-FAQ queries per user per week (while active) | C30: 4 | D30: Estimated | E30: [UX spec; likely 2-5/wk] 4 Smart-FAQ queries per active week.
B31: Avg ACTIVE weeks per user (15-mo journey) | C31: 32 | D31: Estimated | E31: [CDC NIS-Child 2022 + Journey Map tab] 32 active wks across a ~65-wk (15-month) journey. Four peaks: establishment (9wk), return-to-work (7wk), solids (9wk), weaning (7wk). Between peaks users are dormant.
B32: Claude Haiku cost per 1K input tokens ($) | C32: 0.00025 | D32: Sourced | E32: [Anthropic published pricing] Claude Haiku input token cost.
B33: Claude Haiku cost per 1K output tokens ($) | C33: 0.00125 | D33: Sourced | E33: [Anthropic published pricing] Claude Haiku output token cost.
B34: Avg tokens per FAQ query (input) | C34: 500 | E34: Estimate: system prompt ~300 + user query ~200 tokens
B35: Avg tokens per FAQ response (output) | C35: 300 | E35: Estimate: canned answer ~200-400 tokens
B36: Embedding cost per 1M tokens ($) — text-embedding-3-small | C36: 0.02 | E36: Source: technical-design-v1.md — OpenAI text-embedding-3-small
B37: Avg tokens to embed per query | C37: 50 | E37: Estimate: user query ~50 tokens for semantic match
B39: INFRASTRUCTURE (MONTHLY FIXED)
B40: Supabase — pre-launch (free tier) | C40: 0 | E40: Source: technical-design-v1.md — free tier during Phase 0
B41: Supabase Pro (post scale-up) | C41: 25 | D41: Sourced | E41: [technical-design-v1.md; Supabase pricing] Supabase Pro $25/mo.
B42: Supabase upgrade threshold (users) | C42: 500 | D42: Estimated | E42: [Supabase docs] 500-user upgrade threshold. Informational — not wired into COGS.
B43: Vercel — pre-launch (free/hobby) | C43: 0 | E43: Source: technical-design-v1.md — free tier / Lovable Pro handles hosting
B44: Vercel Pro (if needed) | C44: 20 | E44: Source: Vercel pricing — $20/month Pro. Currently on free.
B45: PostHog (free tier) | C45: 0 | E45: Source: technical-design-v1.md — PostHog free tier
B46: Resend email | C46: 0 | E46: Source: technical-design-v1.md — Resend (free tier at v1 scale)
...

Sheet Journey Map
B1: LATCHED — 15-MONTH JOURNEY MAP (CDC-derived)
B2: Evidence base for scope, engagement peaks, and active-weeks assumption. All figures from CDC NIS-Child 2022 birth cohort (n=19,309).
B3: SOURCE: CDC, NIS-Child Data Results — 'Rates of any and exclusive breastfeeding by age among children born in 2022'.
B4: KEY FINDING: median weaning among mothers who pass 6 weeks is ~12 months. A 12-month product would end exactly at the median weaning event.
B6: A. BREASTFEEDING SURVIVAL & WEANING HAZARD
B7: Infant age | C7: % of ALL infants still BF (CDC) | D7: % of 6-WEEK survivors still BF | E7: Monthly weaning hazard | F7: Signal
B8: At birth | C8: 0.857
B9: 1 month | C9: 0.824
B10: 6 weeks (baseline) | C10: 0.805 | D10: 1 | F10: BASELINE — journey survivors
B11: 2 months | C11: 0.785 | D11: 0.976 | E11: 0.047
B12: 3 months | C12: 0.745 | D12: 0.926 | E12: 0.051
B13: 4 months | C13: 0.688 | D13: 0.855 | E13: 0.077 | F13: PEAK 2 — RETURN TO WORK (12-wk leave)
B14: 5 months | C14: 0.645 | D14: 0.802 | E14: 0.062
B15: 6 months | C15: 0.621 | D15: 0.772 | E15: 0.037
B16: 7 months | C16: 0.541 | D16: 0.672 | E16: 0.129 | F16: PEAK 3 — SOLIDS. Biggest single-month cliff.
B17: 8 months | C17: 0.515 | D17: 0.64 | E17: 0.048
B18: 9 months | C18: 0.479 | D18: 0.595 | E18: 0.07
B19: 10 months | C19: 0.449 | D19: 0.558 | E19: 0.063
B20: 11 months | C20: 0.426 | D20: 0.53 | E20: 0.051
B21: 12 months | C21: 0.408 | D21: 0.507 | E21: 0.042 | F21: MEDIAN WEANING — 50% of survivors remain
B22: 13-15 months | E22: 0.118 | F22: PEAK 4 — WEANING (sustained plateau)
B23: 18 months | C23: 0.192 | D23: 0.239 | E23: 0.118 | F23: Only 24% of survivors remain
B26: B. THE FOUR ENGAGEMENT PEAKS → ACTIVE-WEEKS BUILD
B27: # | C27: Peak | D27: Infant age | E27: Active weeks | F27: Why engagement spikes | G27: Evidence
B28: 1 | C28: Milk establishment | D28: Weeks 0–8 | E28: 9 | F28: Latch, supply, pain, weight gain. Highest-risk window — most breastfeeding failure begins here. | G28: CDC: ~60% stop earlier than intended
B29: 2 | C29: Return to work | D29: Months 3–4 | E29: 7 | F29: Pumping logistics, supply maintenance, bottle refusal. US leave is ~12 weeks. | G29: CDC hazard jumps to 7.7% at M3→M4
B30: 3 | C30: Solids introduction | D30: Months 5–7 | E30: 9 | F30: Allergen introduction; how solids affect milk/formula intake. Anxiety spike. | G30: CDC hazard 12.9% at M6→M7 — biggest cliff in year 1
B31: 4 | C31: Weaning | D31: Months 12–15 | E31: 7 | F31: Night weaning, supply reduction, cow's-milk transition, emotional close. | G31: CDC: median weaning ~12mo; hazard ~11.8%/mo through M18
C32: TOTAL ACTIVE WEEKS | E32: =SUM(E28:E31) -> 32 | F32: → feeds Assumptions!C31. Journey spans ~65 wks; only ~32 are active. Between peaks users go dormant.

Sheet GrowthEngine
B1: LATCHED — GROWTH ENGINE (referral-driven)
B2: B2B2C = active partners × referrals/partner × conversion · B2C = marketing ÷ CAC
B3: Month | C3: M1 | D3: M2 | E3: M3 | F3: M4 | G3: M5 | H3: M6 | I3: M7 | J3: M8 | K3: M9 | L3: M10 | M3: M11 | N3: M12 | O3: M13 | P3: M14 | Q3: M15 | R3: M16 | S3: M17 | T3: M18
B4: Active IBCLC partners | C4: 0 | D4: 0 | E4: 0 | F4: 0 | G4: =Assumptions!$C$78 -> 7 | H4: =G4+Assumptions!$C$79 -> 12 | I4: =H4+Assumptions!$C$79 -> 17 | J4: =I4+Assumptions!$C$79 -> 22 | K4: =J4+Assumptions!$C$79 -> 27 | L4: =K4+Assumptions!$C$79 -> 32 | M4: =L4+Assumptions!$C$79 -> 37 | N4: =M4+Assumptions!$C$79 -> 42 | O4: =N4+Assumptions!$C$79 -> 47 | ... T4: =S4+Assumptions!$C$79 -> 72
B5: B2B2C signups | C5: 0 | D5: 0 | E5: 0 | F5: 0 | G5: =ROUND(G4*Assumptions!$C$80*Assumptions!$C$81,0) -> 11 | H5: =ROUND(H4*Assumptions!$C$80*Assumptions!$C$81,0) -> 18 | I5: =ROUND(I4*Assumptions!$C$80*Assumptions!$C$81,0) -> 26 | J5: =ROUND(J4*Assumptions!$C$80*Assumptions!$C$81,0) -> 33 | K5: =ROUND(K4*Assumptions!$C$80*Assumptions!$C$81,0) -> 41 | L5: =ROUND(L4*Assumptions!$C$80*Assumptions!$C$81,0) -> 48 | M5: =ROUND(M4*Assumptions!$C$80*Assumptions!$C$81,0) -> 56 | N5: =ROUND(N4*Assumptions!$C$80*Assumptions!$C$81,0) -> 63 | ... T5: =ROUND(T4*Assumptions!$C$80*Assumptions!$C$81,0) -> 108
B6: B2C signups | C6: 0 | D6: 0 | E6: 0 | F6: 0 | G6: =ROUND(Assumptions!$C$70/Assumptions!$C$14,0) -> 25 | H6: =ROUND(Assumptions!$C$70/Assumptions!$C$14,0) -> 25 | I6: =ROUND(Assumptions!$C$70/Assumptions!$C$14,0) -> 25 | J6: =ROUND(Assumptions!$C$70/Assumptions!$C$14,0) -> 25 | K6: =ROUND(Assumptions!$C$70/Assumptions!$C$14,0) -> 25 | L6: =ROUND(Assumptions!$C$70/Assumptions!$C$14,0) -> 25 | M6: =ROUND(Assumptions!$C$70/Assumptions!$C$14,0) -> 25 | N6: =ROUND(Assumptions!$C$70/Assumptions!$C$14,0) -> 25 | ... T6: =ROUND(Assumptions!$C$70/Assumptions!$C$14,0) -> 25
B7: Total gross signups | C7: =C5+C6 -> 0 | D7: =D5+D6 -> 0 | E7: =E5+E6 -> 0 | F7: =F5+F6 -> 0 | G7: =G5+G6 -> 36 | H7: =H5+H6 -> 43 | I7: =I5+I6 -> 51 | J7: =J5+J6 -> 58 | ... T7: =T5+T6 -> 133

Sheet Revenue
B1: REVENUE — 18-Month Model | V1: net_rev_row=14
B2: (Phase 0 = Months 1-4, Launch = Month 5) | C2: M1 | D2: M2 | E2: M3 | F2: M4 | G2: M5 | H2: M6 | I2: M7 | J2: M8 | K2: M9 | L2: M10 | M2: M11 | N2: M12 | O2: M13 | P2: M14 | Q2: M15 | R2: M16 | S2: M17 | T2: M18 | V2: gross_rev_row=12
B3: USER ACQUISITION | V3: net_signups_row=6
B4: New paid signups (gross) | C4: =GrowthEngine!C7 -> 0 | D4: =GrowthEngine!D7 -> 0 | E4: =GrowthEngine!E7 -> 0 | F4: =GrowthEngine!F7 -> 0 | G4: =GrowthEngine!G7 -> 36 | H4: =GrowthEngine!H7 -> 43 | I4: =GrowthEngine!I7 -> 51 | J4: =GrowthEngine!J7 -> 58 | ... T4: =GrowthEngine!T7 -> 133 | V4: cum_users_row=9
B5: Refunds (gross signups × refund rate) | C5: =-ROUND(C4*Assumptions!$C$6,0) -> 0 | D5: =-ROUND(D4*Assumptions!$C$6,0) -> 0 | E5: =-ROUND(E4*Assumptions!$C$6,0) -> 0 | F5: =-ROUND(F4*Assumptions!$C$6,0) -> 0 | G5: =-ROUND(G4*Assumptions!$C$6,0) -> -4 | H5: =-ROUND(H4*Assumptions!$C$6,0) -> -4 | I5: =-ROUND(I4*Assumptions!$C$6,0) -> -5 | J5: =-ROUND(J4*Assumptions!$C$6,0) -> -6 | ... T5: =-ROUND(T4*Assumptions!$C$6,0) -> -13
B6: Net paid signups | C6: =C4+C5 -> 0 | D6: =D4+D5 -> 0 | E6: =E4+E5 -> 0 | F6: =F4+F5 -> 0 | G6: =G4+G5 -> 32 | H6: =H4+H5 -> 39 | I6: =I4+I5 -> 46 | J6: =J4+J5 -> 52 | ... T6: =T4+T5 -> 120
B7: of which: B2B2C (IBCLC-referred) | C7: =IFERROR(ROUND(C6*(GrowthEngine!C5/GrowthEngine!C7),0),0) -> 0 | D7: =IFERROR(ROUND(D6*(GrowthEngine!D5/GrowthEngine!D7),0),0) -> 0 | E7: =IFERROR(ROUND(E6*(GrowthEngine!E5/GrowthEngine!E7),0),0) -> 0 | F7: =IFERROR(ROUND(F6*(GrowthEngine!F5/GrowthEngine!F7),0),0) -> 0 | G7: =IFERROR(ROUND(G6*(GrowthEngine!G5/GrowthEngine!G7),0),0) -> 10 | H7: =IFERROR(ROUND(H6*(GrowthEngine!H5/GrowthEngine!H7),0),0) -> 16 | I7: =IFERROR(ROUND(I6*(GrowthEngine!I5/GrowthEngine!I7),0),0) -> 23 | J7: =IFERROR(ROUND(J6*(GrowthEngine!J5/GrowthEngine!J7),0),0) -> 30 | ... T7: =IFERROR(ROUND(T6*(GrowthEngine!T5/GrowthEngine!T7),0),0) -> 97
B8: of which: Direct B2C | C8: =C6-C7 -> 0 | D8: =D6-D7 -> 0 | E8: =E6-E7 -> 0 | F8: =F6-F7 -> 0 | G8: =G6-G7 -> 22 | H8: =H6-H7 -> 23 | I8: =I6-I7 -> 23 | J8: =J6-J7 -> 22 | ... T8: =T6-T7 -> 23
B9: Cumulative total users | C9: =C6 -> 0 | D9: =C9+D6 -> 0 | E9: =D9+E6 -> 0 | F9: =E9+F6 -> 0 | G9: =F9+G6 -> 32 | H9: =G9+H6 -> 71 | I9: =H9+I6 -> 117 | J9: =I9+J6 -> 169 | K9: =J9+K6 -> 228 | ... T9: =S9+T6 -> 1064
B11: GROSS REVENUE
B12: Gross revenue (net signups × $49) | C12: =C6*Assumptions!$C$4 -> 0 | D12: =D6*Assumptions!$C$4 -> 0 | E12: =E6*Assumptions!$C$4 -> 0 | F12: =F6*Assumptions!$C$4 -> 0 | G12: =G6*Assumptions!$C$4 -> 1568 | H12: =H6*Assumptions!$C$4 -> 1911 | I12: =I6*Assumptions!$C$4 -> 2254 | J12: =J6*Assumptions!$C$4 -> 2548 | ... T12: =T6*Assumptions!$C$4 -> 5880
B13: Stripe fees (–2.9% – $0.30/txn) | C13: =-((C4*Assumptions!$C$4*Assumptions!$C$10)+(C4*Assumptions!$C$11)) -> 0 | D13: =-((D4*Assumptions!$C$4*Assumptions!$C$10)+(D4*Assumptions!$C$11)) -> 0 | E13: =-((E4*Assumptions!$C$4*Assumptions!$C$10)+(E4*Assumptions!$C$11)) -> 0 | F13: =-((F4*Assumptions!$C$4*Assumptions!$C$10)+(F4*Assumptions!$C$11)) -> 0 | G13: =-((G4*Assumptions!$C$4*Assumptions!$C$10)+(G4*Assumptions!$C$11)) -> -61.956 | H13: =-((H4*Assumptions!$C$4*Assumptions!$C$10)+(H4*Assumptions!$C$11)) -> -74.003 | I13: =-((I4*Assumptions!$C$4*Assumptions!$C$10)+(I4*Assumptions!$C$11)) -> -87.771 | J13: =-((J4*Assumptions!$C$4*Assumptions!$C$10)+(J4*Assumptions!$C$11)) -> -99.818 | ... T13: =-((T4*Assumptions!$C$4*Assumptions!$C$10)+(T4*Assumptions!$C$11)) -> -228.893
B14: Net revenue (after Stripe) | C14: =C12+C13 -> 0 | D14: =D12+D13 -> 0 | E14: =E12+E13 -> 0 | F14: =F12+F13 -> 0 | G14: =G12+G13 -> 1506.044 | H14: =H12+H13 -> 1836.997 | I14: =I12+I13 -> 2166.229 | J14: =J12+J13 -> 2448.182 | ... T14: =T12+T13 -> 5651.107

Sheet COGS
B1: COGS — 18-Month Model | V1: total_cogs_row=13
B2: (Phase 0 = Months 1-4, Launch = Month 5) | C2: M1 | D2: M2 | E2: M3 | F2: M4 | G2: M5 | H2: M6 | I2: M7 | J2: M8 | K2: M9 | L2: M10 | M2: M11 | N2: M12 | O2: M13 | P2: M14 | Q2: M15 | R2: M16 | S2: M17 | T2: M18
B3: VARIABLE COSTS (PER USER / PER QUERY)
B4: LLM cost per active user ($/user) [formula-driven] | C4: =IFERROR((Assumptions!$C$30*Assumptions!$C$31)*((Assumptions!$C$34/1000*Assumptions!$C$32)+(Assumptions!$C$35/1000*Assumptions!$C$33)+(Assumptions!$C$37/1000000*Assumptions!$C$36)),"?") -> 0.064128 | D4: =IFERROR((Assumptions!$C$30*Assumptions!$C$31)*((Assumptions!$C$34/1000*Assumptions!$C$32)+(Assumptions!$C$35/1000*Assumptions!$C$33)+(Assumptions!$C$37/1000000*Assumptions!$C$36)),"?") -> 0.064128 | E4: =IFERROR((Assumptions!$C$30*Assumptions!$C$31)*((Assumptions!$C$34/1000*Assumptions!$C$32)+(Assumptions!$C$35/1000*Assumptions!$C$33)+(Assumptions!$C$37/1000000*Assumptions!$C$36)),"?") -> 0.064128 | F4: =IFERROR((Assumptions!$C$30*Assumptions!$C$31)*((Assumptions!$C$34/1000*Assumptions!$C$32)+(Assumptions!$C$35/1000*Assumptions!$C$33)+(Assumptions!$C$37/1000000*Assumptions!$C$36)),"?") -> 0.064128 | G4: =IFERROR((Assumptions!$C$30*Assumptions!$C$31)*((Assumptions!$C$34/1000*Assumptions!$C$32)+(Assumptions!$C$35/1000*Assumptions!$C$33)+(Assumptions!$C$37/1000000*Assumptions!$C$36)),"?") -> 0.064128 | H4: =IFERROR((Assumptions!$C$30*Assumptions!$C$31)*((Assumptions!$C$34/1000*Assumptions!$C$32)+(Assumptions!$C$35/1000*Assumptions!$C$33)+(Assumptions!$C$37/1000000*Assumptions!$C$36)),"?") -> 0.064128 | I4: =IFERROR((Assumptions!$C$30*Assumptions!$C$31)*((Assumptions!$C$34/1000*Assumptions!$C$32)+(Assumptions!$C$35/1000*Assumptions!$C$33)+(Assumptions!$C$37/1000000*Assumptions!$C$36)),"?") -> 0.064128 | J4: =IFERROR((Assumptions!$C$30*Assumptions!$C$31)*((Assumptions!$C$34/1000*Assumptions!$C$32)+(Assumptions!$C$35/1000*Assumptions!$C$33)+(Assumptions!$C$37/1000000*Assumptions!$C$36)),"?") -> 0.064128 | ... T4: =IFERROR((Assumptions!$C$30*Assumptions!$C$31)*((Assumptions!$C$34/1000*Assumptions!$C$32)+(Assumptions!$C$35/1000*Assumptions!$C$33)+(Assumptions!$C$37/1000000*Assumptions!$C$36)),"?") -> 0.064128
B5: Total LLM cost (LLM/user × new signups) | C5: =IFERROR(C4*Revenue!C6,0) -> 0 | D5: =IFERROR(D4*Revenue!D6,0) -> 0 | E5: =IFERROR(E4*Revenue!E6,0) -> 0 | F5: =IFERROR(F4*Revenue!F6,0) -> 0 | G5: =IFERROR(G4*Revenue!G6,0) -> 2.052096 | H5: =IFERROR(H4*Revenue!H6,0) -> 2.500992 | I5: =IFERROR(I4*Revenue!I6,0) -> 2.949888 | J5: =IFERROR(J4*Revenue!J6,0) -> 3.334656 | ... T5: =IFERROR(T4*Revenue!T6,0) -> 7.69536
B7: FIXED INFRASTRUCTURE (MONTHLY)
B8: Supabase | C8: =Assumptions!$C$40 -> 0 | D8: =Assumptions!$C$40 -> 0 | E8: =Assumptions!$C$40 -> 0 | F8: =Assumptions!$C$40 -> 0 | G8: =Assumptions!$C$41 -> 25 | H8: =Assumptions!$C$41 -> 25 | I8: =Assumptions!$C$41 -> 25 | J8: =Assumptions!$C$41 -> 25 | K8: =Assumptions!$C$41 -> 25 | L8: =Assumptions!$C$41 -> 25 | M8: =Assumptions!$C$41 -> 25 | N8: =Assumptions!$C$41 -> 25 | ... T8: =Assumptions!$C$41 -> 25
B9: Vercel hosting | C9: =Assumptions!$C$43 -> 0 | D9: =Assumptions!$C$43 -> 0 | E9: =Assumptions!$C$43 -> 0 | F9: =Assumptions!$C$43 -> 0 | G9: =Assumptions!$C$43 -> 0 | H9: =Assumptions!$C$43 -> 0 | I9: =Assumptions!$C$43 -> 0 | J9: =Assumptions!$C$43 -> 0 | ... T9: =Assumptions!$C$43 -> 0
B10: InfantRisk.com subscription | C10: =Assumptions!$C$47 -> 10 | D10: =Assumptions!$C$47 -> 10 | E10: =Assumptions!$C$47 -> 10 | F10: =Assumptions!$C$47 -> 10 | G10: =Assumptions!$C$47 -> 10 | H10: =Assumptions!$C$47 -> 10 | I10: =Assumptions!$C$47 -> 10 | J10: =Assumptions!$C$47 -> 10 | ... T10: =Assumptions!$C$47 -> 10
B12: TOTAL COGS
B13: Total COGS | C13: =C5+C8+C9+C10 -> 10 | D13: =D5+D8+D9+D10 -> 10 | E13: =E5+E8+E9+E10 -> 10 | F13: =F5+F8+F9+F10 -> 10 | G13: =G5+G8+G9+G10 -> 37.052096 | H13: =H5+H8+H9+H10 -> 37.500992 | I13: =I5+I8+I9+I10 -> 37.949888 | J13: =J5+J8+J9+J10 -> 38.334656 | ... T13: =T5+T8+T9+T10 -> 42.69536

Sheet OpEx
B1: OPEX — 18-Month Model | V1: total_opex_row=25
B2: (Phase 0 = Months 1-4, Launch = Month 5) | C2: M1 | D2: M2 | E2: M3 | F2: M4 | G2: M5 | H2: M6 | I2: M7 | J2: M8 | K2: M9 | L2: M10 | M2: M11 | N2: M12 | O2: M13 | P2: M14 | Q2: M15 | R2: M16 | S2: M17 | T2: M18
B3: ADVISOR FEES
B4: IBCLC advisor — pre-launch (low estimate) | C4: =ROUND((Assumptions!$C$63/4)*Assumptions!$C$61,0) -> 1688 | D4: =ROUND((Assumptions!$C$63/4)*Assumptions!$C$61,0) -> 1688 | E4: =ROUND((Assumptions!$C$63/4)*Assumptions!$C$61,0) -> 1688 | F4: =ROUND((Assumptions!$C$63/4)*Assumptions!$C$61,0) -> 1688 | G4: 0 | H4: 0 | I4: 0 | J4: 0 | K4: 0 | L4: 0 | M4: 0 | N4: 0 | O4: 0 | P4: 0 | Q4: 0 | R4: 0 | S4: 0 | T4: 0
B5: IBCLC advisor — pre-launch (high estimate) | C5: =ROUND((Assumptions!$C$64/4)*Assumptions!$C$62,0) -> 4350 | D5: =ROUND((Assumptions!$C$64/4)*Assumptions!$C$62,0) -> 4350 | E5: =ROUND((Assumptions!$C$64/4)*Assumptions!$C$62,0) -> 4350 | F5: =ROUND((Assumptions!$C$64/4)*Assumptions!$C$62,0) -> 4350 | G5: 0 | H5: 0 | I5: 0 | J5: 0 | K5: 0 | L5: 0 | M5: 0 | N5: 0 | O5: 0 | P5: 0 | Q5: 0 | R5: 0 | S5: 0 | T5: 0
B6: IBCLC advisor — ongoing (post-launch) | C6: 0 | D6: 0 | E6: 0 | F6: 0 | G6: =IFERROR(Assumptions!$C$66*Assumptions!$C$61,"?") -> 450 | H6: =IFERROR(Assumptions!$C$66*Assumptions!$C$61,"?") -> 450 | I6: =IFERROR(Assumptions!$C$66*Assumptions!$C$61,"?") -> 450 | J6: =IFERROR(Assumptions!$C$66*Assumptions!$C$61,"?") -> 450 | K6: =IFERROR(Assumptions!$C$66*Assumptions!$C$61,"?") -> 450 | L6: =IFERROR(Assumptions!$C$66*Assumptions!$C$61,"?") -> 450 | M6: =IFERROR(Assumptions!$C$66*Assumptions!$C$61,"?") -> 450 | N6: =IFERROR(Assumptions!$C$66*Assumptions!$C$61,"?") -> 450 | ... T6: =IFERROR(Assumptions!$C$66*Assumptions!$C$61,"?") -> 450
B8: RESEARCH & VALIDATION (PHASE 0)
B9: Research survey incentives ($200 total) | C9: =Assumptions!$C$52 -> 200 | D9: 0 | E9: 0 | F9: 0 | G9: 0 | H9: 0 | I9: 0 | J9: 0 | K9: 0 | L9: 0 | M9: 0 | N9: 0 | O9: 0 | P9: 0 | Q9: 0 | R9: 0 | S9: 0 | T9: 0
B10: Cold IBCLC interview incentives ($375 total) | C10: =Assumptions!$C$53 -> 375 | D10: 0 | E10: 0 | F10: 0 | G10: 0 | H10: 0 | I10: 0 | J10: 0 | K10: 0 | L10: 0 | M10: 0 | N10: 0 | O10: 0 | P10: 0 | Q10: 0 | R10: 0 | S10: 0 | T10: 0
B11: Other validation costs (ruler test, WTP, legal) | C11: =SUM(Assumptions!$C$54:$C$57) -> 530 | D11: 0 | E11: 0 | F11: 0 | G11: 0 | H11: 0 | I11: 0 | J11: 0 | K11: 0 | L11: 0 | M11: 0 | N11: 0 | O11: 0 | P11: 0 | Q11: 0 | R11: 0 | S11: 0 | T11: 0
B13: MARKETING
B14: Paid marketing | C14: =Assumptions!$C$69 -> 0 | D14: =Assumptions!$C$69 -> 0 | E14: =Assumptions!$C$69 -> 0 | F14: =Assumptions!$C$69 -> 0 | G14: =IFERROR(Assumptions!$C$70,"?") -> 750 | H14: =IFERROR(Assumptions!$C$70,"?") -> 750 | I14: =IFERROR(Assumptions!$C$70,"?") -> 750 | J14: =IFERROR(Assumptions!$C$70,"?") -> 750 | K14: =IFERROR(Assumptions!$C$70,"?") -> 750 | L14: =IFERROR(Assumptions!$C$70,"?") -> 750 | M14: =IFERROR(Assumptions!$C$70,"?") -> 750 | N14: =IFERROR(Assumptions!$C$70,"?") -> 750 | ... T14: =IFERROR(Assumptions!$C$70,"?") -> 750
B15: IBCLC partner outreach / referral program | C15: =IFERROR(Assumptions!$C$71,"?") -> 75 | D15: =IFERROR(Assumptions!$C$71,"?") -> 75 | E15: =IFERROR(Assumptions!$C$71,"?") -> 75 | F15: =IFERROR(Assumptions!$C$71,"?") -> 75 | G15: =IFERROR(Assumptions!$C$71,"?") -> 75 | H15: =IFERROR(Assumptions!$C$71,"?") -> 75 | I15: =IFERROR(Assumptions!$C$71,"?") -> 75 | J15: =IFERROR(Assumptions!$C$71,"?") -> 75 | ... T15: =IFERROR(Assumptions!$C$71,"?") -> 75
B17: PEOPLE
B18: Founder salary | C18: =IFERROR(Assumptions!$C$74,"?") -> 0 | D18: =IFERROR(Assumptions!$C$74,"?") -> 0 | E18: =IFERROR(Assumptions!$C$74,"?") -> 0 | F18: =IFERROR(Assumptions!$C$74,"?") -> 0 | G18: =IFERROR(Assumptions!$C$74,"?") -> 0 | H18: =IFERROR(Assumptions!$C$74,"?") -> 0 | I18: =IFERROR(Assumptions!$C$74,"?") -> 0 | J18: =IFERROR(Assumptions!$C$74,"?") -> 0 | ... T18: =IFERROR(Assumptions!$C$74,"?") -> 0
B19: Contractors / freelancers | C19: =IFERROR(Assumptions!$C$75,"?") -> 0 | D19: =IFERROR(Assumptions!$C$75,"?") -> 0 | E19: =IFERROR(Assumptions!$C$75,"?") -> 0 | F19: =IFERROR(Assumptions!$C$75,"?") -> 0 | G19: =IFERROR(Assumptions!$C$75,"?") -> 0 | H19: =IFERROR(Assumptions!$C$75,"?") -> 0 | I19: =IFERROR(Assumptions!$C$75,"?") -> 0 | J19: =IFERROR(Assumptions!$C$75,"?") -> 0 | ... T19: =IFERROR(Assumptions!$C$75,"?") -> 0
B21: G&A / TOOLS
B22: Other SaaS & tools | C22: =IFERROR(Assumptions!$C$49,"?") -> 20 | D22: =IFERROR(Assumptions!$C$49,"?") -> 20 | E22: =IFERROR(Assumptions!$C$49,"?") -> 20 | F22: =IFERROR(Assumptions!$C$49,"?") -> 20 | G22: =IFERROR(Assumptions!$C$49,"?") -> 20 | H22: =IFERROR(Assumptions!$C$49,"?") -> 20 | I22: =IFERROR(Assumptions!$C$49,"?") -> 20 | J22: =IFERROR(Assumptions!$C$49,"?") -> 20 | ... T22: =IFERROR(Assumptions!$C$49,"?") -> 20
B24: TOTAL OPEX
B25: Total OpEx (base — low advisor) | C25: =IFERROR(IF(ISNUMBER(C4),C4,0)+IF(ISNUMBER(C6),C6,0)+IF(ISNUMBER(C9),C9,0)+IF(ISNUMBER(C10),C10,0)+IF(ISNUMBER(C11),C11,0)+IF(ISNUMBER(C14),C14,0)+IF(ISNUMBER(C15),C15,0)+IF(ISNUMBER(C18),C18,0)+IF(ISNUMBER(C19),C19,0)+IF(ISNUMBER(C22),C22,0),0) -> 2888 | D25: =IFERROR(IF(ISNUMBER(D4),D4,0)+IF(ISNUMBER(D6),D6,0)+IF(ISNUMBER(D9),D9,0)+IF(ISNUMBER(D10),D10,0)+IF(ISNUMBER(D11),D11,0)+IF(ISNUMBER(D14),D14,0)+IF(ISNUMBER(D15),D15,0)+IF(ISNUMBER(D18),D18,0)+IF(ISNUMBER(D19),D19,0)+IF(ISNUMBER(D22),D22,0),0) -> 1783 | E25: =IFERROR(IF(ISNUMBER(E4),E4,0)+IF(ISNUMBER(E6),E6,0)+IF(ISNUMBER(E9),E9,0)+IF(ISNUMBER(E10),E10,0)+IF(ISNUMBER(E11),E11,0)+IF(ISNUMBER(E14),E14,0)+IF(ISNUMBER(E15),E15,0)+IF(ISNUMBER(E18),E18,0)+IF(ISNUMBER(E19),E19,0)+IF(ISNUMBER(E22),E22,0),0) -> 1783 | F25: =IFERROR(IF(ISNUMBER(F4),F4,0)+IF(ISNUMBER(F6),F6,0)+IF(ISNUMBER(F9),F9,0)+IF(ISNUMBER(F10),F10,0)+IF(ISNUMBER(F11),F11,0)+IF(ISNUMBER(F14),F14,0)+IF(ISNUMBER(F15),F15,0)+IF(ISNUMBER(F18),F18,0)+IF(ISNUMBER(F19),F19,0)+IF(ISNUMBER(F22),F22,0),0) -> 1783 | G25: =IFERROR(IF(ISNUMBER(G4),G4,0)+IF(ISNUMBER(G6),G6,0)+IF(ISNUMBER(G9),G9,0)+IF(ISNUMBER(G10),G10,0)+IF(ISNUMBER(G11),G11,0)+IF(ISNUMBER(G14),G14,0)+IF(ISNUMBER(G15),G15,0)+IF(ISNUMBER(G18),G18,0)+IF(ISNUMBER(G19),G19,0)+IF(ISNUMBER(G22),G22,0),0) -> 1295 | H25: =IFERROR(IF(ISNUMBER(H4),H4,0)+IF(ISNUMBER(H6),H6,0)+IF(ISNUMBER(H9),H9,0)+IF(ISNUMBER(H10),H10,0)+IF(ISNUMBER(H11),H11,0)+IF(ISNUMBER(H14),H14,0)+IF(ISNUMBER(H15),H15,0)+IF(ISNUMBER(H18),H18,0)+IF(ISNUMBER(H19),H19,0)+IF(ISNUMBER(H22),H22,0),0) -> 1295 | I25: =IFERROR(IF(ISNUMBER(I4),I4,0)+IF(ISNUMBER(I6),I6,0)+IF(ISNUMBER(I9),I9,0)+IF(ISNUMBER(I10),I10,0)+IF(ISNUMBER(I11),I11,0)+IF(ISNUMBER(I14),I14,0)+IF(ISNUMBER(I15),I15,0)+IF(ISNUMBER(I18),I18,0)+IF(ISNUMBER(I19),I19,0)+IF(ISNUMBER(I22),I22,0),0) -> 1295 | J25: =IFERROR(IF(ISNUMBER(J4),J4,0)+IF(ISNUMBER(J6),J6,0)+IF(ISNUMBER(J9),J9,0)+IF(ISNUMBER(J10),J10,0)+IF(ISNUMBER(J11),J11,0)+IF(ISNUMBER(J14),J14,0)+IF(ISNUMBER(J15),J15,0)+IF(ISNUMBER(J18),J18,0)+IF(ISNUMBER(J19),J19,0)+IF(ISNUMBER(J22),J22,0),0) -> 1295 | ... T25: =IFERROR(IF(ISNUMBER(T4),T4,0)+IF(ISNUMBER(T6),T6,0)+IF(ISNUMBER(T9),T9,0)+IF(ISNUMBER(T10),T10,0)+IF(ISNUMBER(T11),T11,0)+IF(ISNUMBER(T14),T14,0)+IF(ISNUMBER(T15),T15,0)+IF(ISNUMBER(T18),T18,0)+IF(ISNUMBER(T19),T19,0)+IF(ISNUMBER(T22),T22,0),0) -> 1295

Sheet P&L
B1: P&L — 18-Month Model
B2: (Phase 0 = Months 1-4, Launch = Month 5) | C2: M1 | D2: M2 | E2: M3 | F2: M4 | G2: M5 | H2: M6 | I2: M7 | J2: M8 | K2: M9 | L2: M10 | M2: M11 | N2: M12 | O2: M13 | P2: M14 | Q2: M15 | R2: M16 | S2: M17 | T2: M18
B3: PROFIT & LOSS SUMMARY
B4: Net Revenue | C4: =Revenue!C14 -> 0 | D4: =Revenue!D14 -> 0 | E4: =Revenue!E14 -> 0 | F4: =Revenue!F14 -> 0 | G4: =Revenue!G14 -> 1506.044 | H4: =Revenue!H14 -> 1836.997 | I4: =Revenue!I14 -> 2166.229 | J4: =Revenue!J14 -> 2448.182 | ... T4: =Revenue!T14 -> 5651.107
B5: Total COGS | C5: =-COGS!C13 -> -10 | D5: =-COGS!D13 -> -10 | E5: =-COGS!E13 -> -10 | F5: =-COGS!F13 -> -10 | G5: =-COGS!G13 -> -37.052096 | H5: =-COGS!H13 -> -37.500992 | I5: =-COGS!I13 -> -37.949888 | J5: =-COGS!J13 -> -38.334656 | ... T5: =-COGS!T13 -> -42.69536
B6: Gross Profit | C6: =IFERROR(C4+C5,0) -> -10 | D6: =IFERROR(D4+D5,0) -> -10 | E6: =IFERROR(E4+E5,0) -> -10 | F6: =IFERROR(F4+F5,0) -> -10 | G6: =IFERROR(G4+G5,0) -> 1468.9919 | H6: =IFERROR(H4+H5,0) -> 1799.496 | I6: =IFERROR(I4+I5,0) -> 2128.2791 | J6: =IFERROR(J4+J5,0) -> 2409.8473 | ... T6: =IFERROR(T4+T5,0) -> 5608.4116
B7: Gross Margin % | C7: =IFERROR(C6/C4,"-") -> - | D7: =IFERROR(D6/D4,"-") -> - | E7: =IFERROR(E6/E4,"-") -> - | F7: =IFERROR(F6/F4,"-") -> - | G7: =IFERROR(G6/G4,"-") -> 0.97539773 | H7: =IFERROR(H6/H4,"-") -> 0.97958571 | I7: =IFERROR(I6/I4,"-") -> 0.98248113 | J7: =IFERROR(J6/J4,"-") -> 0.98434158 | ... T7: =IFERROR(T6/T4,"-") -> 0.99244478
B9: Total OpEx | C9: =-OpEx!C25 -> -2888 | D9: =-OpEx!D25 -> -1783 | E9: =-OpEx!E25 -> -1783 | F9: =-OpEx!F25 -> -1783 | G9: =-OpEx!G25 -> -1295 | H9: =-OpEx!H25 -> -1295 | I9: =-OpEx!I25 -> -1295 | J9: =-OpEx!J25 -> -1295 | ... T9: =-OpEx!T25 -> -1295
B10: EBITDA / Net Operating Income | C10: =IFERROR(C6+C9,0) -> -2898 | D10: =IFERROR(D6+D9,0) -> -1793 | E10: =IFERROR(E6+E9,0) -> -1793 | F10: =IFERROR(F6+F9,0) -> -1793 | G10: =IFERROR(G6+G9,0) -> 173.9919 | H10: =IFERROR(H6+H9,0) -> 504.49601 | I10: =IFERROR(I6+I9,0) -> 833.27911 | J10: =IFERROR(J6+J9,0) -> 1114.8473 | ... T10: =IFERROR(T6+T9,0) -> 4313.4116
B11: Cumulative Cash Position (simplified) | C11: =C10 -> -2898 | D11: =C11+D10 -> -4691 | E11: =D11+E10 -> -6484 | F11: =E11+F10 -> -8277 | G11: =F11+G10 -> -8103.0081 | H11: =G11+H10 -> -7598.5121 | I11: =H11+I10 -> -6765.233 | J11: =I11+J10 -> -5650.3856 | K11: =J11+K10 -> -4206.7552 | ... T11: =S11+T10 -> 23134.825
B13: SUPPORTING METRICS
B14: New Paid Signups (net) | C14: =Revenue!C6 -> 0 | D14: =Revenue!D6 -> 0 | E14: =Revenue!E6 -> 0 | F14: =Revenue!F6 -> 0 | G14: =Revenue!G6 -> 32 | H14: =Revenue!H6 -> 39 | I14: =Revenue!I6 -> 46 | J14: =Revenue!J6 -> 52 | ... T14: =Revenue!T6 -> 120
B15: Cumulative Users | C15: =Revenue!C9 -> 0 | D15: =Revenue!D9 -> 0 | E15: =Revenue!E9 -> 0 | F15: =Revenue!F9 -> 0 | G15: =Revenue!G9 -> 32 | H15: =Revenue!H9 -> 71 | I15: =Revenue!I9 -> 117 | J15: =Revenue!J9 -> 169 | ... T15: =Revenue!T9 -> 1064

Sheet Scenarios
B1: LATCHED — REFERRAL-DRIVEN GROWTH SCENARIOS
B2: Lever = new IBCLC partners onboarded/month · B2C fixed (spend÷CAC) · 18-month
B4: Month | C4: M1 | D4: M2 | E4: M3 | F4: M4 | G4: M5 | H4: M6 | I4: M7 | J4: M8 | K4: M9 | L4: M10 | M4: M11 | N4: M12 | O4: M13 | P4: M14 | Q4: M15 | R4: M16 | S4: M17 | T4: M18
B6: SCENARIO COMPARISON
B7: Scenario | C7: Partners +/mo | D7: Signups M18/mo | E7: Net rev (18-mo) | F7: Cum users M18 | G7: Cum cash M18 | H7: Breakeven mo | I7: Peak cash need
B8: Conservative | C8: =C15 -> 3 | D8: =T18 -> 94 | E8: =SUM(C21:T21) -> 38515.89 | F8: =T20 -> 818 | G8: =T26 -> 11566.433 | H8: =IF(COUNT(C27:T27)=0,"—",MIN(C27:T27)) -> 13 | I8: =MIN(C26:T26) -> -8277
B9: Base | C9: =C32 -> 5 | D9: =T35 -> 133 | E9: =SUM(C38:T38) -> 50100.057 | F9: =T37 -> 1064 | G9: =T43 -> 23134.825 | H9: =IF(COUNT(C44:T44)=0,"—",MIN(C44:T44)) -> 12 | I9: =MIN(C43:T43) -> -8277
B10: Aggressive | C10: =C49 -> 8 | D10: =T52 -> 192 | E10: =SUM(C55:T55) -> 67617.284 | F10: =T54 -> 1436 | G10: =T60 -> 40628.196 | H10: =IF(COUNT(C61:T61)=0,"—",MIN(C61:T61)) -> 10 | I10: =MIN(C60:T60) -> -8277
B14: CONSERVATIVE — 3 partners/mo
B15: New partners/month | C15: 3
B17: Active partners | C17: 0 | D17: 0 | E17: 0 | F17: 0 | G17: =Assumptions!$C$78 -> 7 | H17: =G17+$C$15 -> 10 | I17: =H17+$C$15 -> 13 | J17: =I17+$C$15 -> 16 | K17: =J17+$C$15 -> 19 | L17: =K17+$C$15 -> 22 | M17: =L17+$C$15 -> 25 | N17: =M17+$C$15 -> 28 | O17: =N17+$C$15 -> 31 | ... T17: =S17+$C$15 -> 46
B18: Gross signups | C18: 0 | D18: 0 | E18: 0 | F18: 0 | G18: =ROUND(G17*Assumptions!$C$80*Assumptions!$C$81,0)+ROUND(Assumptions!$C$70/Assumptions!$C$14,0) -> 36 | H18: =ROUND(H17*Assumptions!$C$80*Assumptions!$C$81,0)+ROUND(Assumptions!$C$70/Assumptions!$C$14,0) -> 40 | I18: =ROUND(I17*Assumptions!$C$80*Assumptions!$C$81,0)+ROUND(Assumptions!$C$70/Assumptions!$C$14,0) -> 45 | J18: =ROUND(J17*Assumptions!$C$80*Assumptions!$C$81,0)+ROUND(Assumptions!$C$70/Assumptions!$C$14,0) -> 49 | K18: =ROUND(K17*Assumptions!$C$80*Assumptions!$C$81,0)+ROUND(Assumptions!$C$70/Assumptions!$C$14,0) -> 54 | L18: =ROUND(L17*Assumptions!$C$80*Assumptions!$C$81,0)+ROUND(Assumptions!$C$70/Assumptions!$C$14,0) -> 58 | M18: =ROUND(M17*Assumptions!$C$80*Assumptions!$C$81,0)+ROUND(Assumptions!$C$70/Assumptions!$C$14,0) -> 63 | N18: =ROUND(N17*Assumptions!$C$80*Assumptions!$C$81,0)+ROUND(Assumptions!$C$70/Assumptions!$C$14,0) -> 67 | ... T18: =ROUND(T17*Assumptions!$C$80*Assumptions!$C$81,0)+ROUND(Assumptions!$C$70/Assumptions!$C$14,0) -> 94
B19: Net signups | C19: 0 | D19: 0 | E19: 0 | F19: 0 | G19: =G18-ROUND(G18*Assumptions!$C$6,0) -> 32 | H19: =H18-ROUND(H18*Assumptions!$C$6,0) -> 36 | I19: =I18-ROUND(I18*Assumptions!$C$6,0) -> 40 | J19: =J18-ROUND(J18*Assumptions!$C$6,0) -> 44 | K19: =K18-ROUND(K18*Assumptions!$C$6,0) -> 49 | L19: =L18-ROUND(L18*Assumptions!$C$6,0) -> 52 | M19: =M18-ROUND(M18*Assumptions!$C$6,0) -> 57 | N19: =N18-ROUND(N18*Assumptions!$C$6,0) -> 60 | ... T19: =T18-ROUND(T18*Assumptions!$C$6,0) -> 85
B20: Cumulative users | C20: =C19 -> 0 | D20: =C20+D19 -> 0 | E20: =D20+E19 -> 0 | F20: =E20+F19 -> 0 | G20: =F20+G19 -> 32 | H20: =G20+H19 -> 68 | I20: =H20+I19 -> 108 | J20: =I20+J19 -> 152 | K20: =J20+K19 -> 201 | ... T20: =S20+T19 -> 818
B21: Net revenue | C21: 0 | D21: 0 | E21: 0 | F21: 0 | G21: =(G19*Assumptions!$C$4)-((G18*Assumptions!$C$4*Assumptions!$C$10)+(G18*Assumptions!$C$11)) -> 1506.044 | H21: =(H19*Assumptions!$C$4)-((H18*Assumptions!$C$4*Assumptions!$C$10)+(H18*Assumptions!$C$11)) -> 1695.16 | I21: =(I19*Assumptions!$C$4)-((I18*Assumptions!$C$4*Assumptions!$C$10)+(I18*Assumptions!$C$11)) -> 1882.555 | J21: =(J19*Assumptions!$C$4)-((J18*Assumptions!$C$4*Assumptions!$C$10)+(J18*Assumptions!$C$11)) -> 2071.671 | K21: =(K19*Assumptions!$C$4)-((K18*Assumptions!$C$4*Assumptions!$C$10)+(K18*Assumptions!$C$11)) -> 2308.066 | L21: =(L19*Assumptions!$C$4)-((L18*Assumptions!$C$4*Assumptions!$C$10)+(L18*Assumptions!$C$11)) -> 2448.182 | M21: =(M19*Assumptions!$C$4)-((M18*Assumptions!$C$4*Assumptions!$C$10)+(M18*Assumptions!$C$11)) -> 2684.577 | N21: =(N19*Assumptions!$C$4)-((N18*Assumptions!$C$4*Assumptions!$C$10)+(N18*Assumptions!$C$11)) -> 2824.693 | ... T21: =(T19*Assumptions!$C$4)-((T18*Assumptions!$C$4*Assumptions!$C$10)+(T18*Assumptions!$C$11)) -> 4003.226
B22: Total COGS | C22: =(COGS!C8+COGS!C9+COGS!C10)+(COGS!$I$4*C19) -> 10 | D22: =(COGS!D8+COGS!D9+COGS!D10)+(COGS!$I$4*D19) -> 10 | E22: =(COGS!E8+COGS!E9+COGS!E10)+(COGS!$I$4*E19) -> 10 | F22: =(COGS!F8+COGS!F9+COGS!F10)+(COGS!$I$4*F19) -> 10 | G22: =(COGS!G8+COGS!G9+COGS!G10)+(COGS!$I$4*G19) -> 37.052096 | H22: =(COGS!H8+COGS!H9+COGS!H10)+(COGS!$I$4*H19) -> 37.308608 | I22: =(COGS!I8+COGS!I9+COGS!I10)+(COGS!$I$4*I19) -> 37.56512 | J22: =(COGS!J8+COGS!J9+COGS!J10)+(COGS!$I$4*J19) -> 37.821632 | ... T22: =(COGS!T8+COGS!T9+COGS!T10)+(COGS!$I$4*T19) -> 40.45088
B23: Gross profit | C23: =C21-C22 -> -10 | D23: =D21-D22 -> -10 | E23: =E21-E22 -> -10 | F23: =F21-F22 -> -10 | G23: =G21-G22 -> 1468.9919 | H23: =H21-H22 -> 1657.8514 | I23: =I21-I22 -> 1844.9899 | J23: =J21-J22 -> 2033.8494 | ... T23: =T21-T22 -> 3962.7751
B24: Total OpEx | C24: =OpEx!C25 -> 2888 | D24: =OpEx!D25 -> 1783 | E24: =OpEx!E25 -> 1783 | F24: =OpEx!F25 -> 1783 | G24: =OpEx!G25 -> 1295 | H24: =OpEx!H25 -> 1295 | I24: =OpEx!I25 -> 1295 | J24: =OpEx!J25 -> 1295 | ... T24: =OpEx!T25 -> 1295
B25: EBITDA | C25: =C23-C24 -> -2898 | D25: =D23-D24 -> -1793 | E25: =E23-E24 -> -1793 | F25: =F23-F24 -> -1793 | G25: =G23-G24 -> 173.9919 | H25: =H23-H24 -> 362.85139 | I25: =I23-I24 -> 549.98988 | J25: =J23-J24 -> 738.84937 | ... T25: =T23-T24 -> 2667.7751
B26: Cumulative cash | C26: =C25 -> -2898 | D26: =C26+D25 -> -4691 | E26: =D26+E25 -> -6484 | F26: =E26+F25 -> -8277 | G26: =F26+G25 -> -8103.0081 | H26: =G26+H25 -> -7740.1567 | I26: =H26+I25 -> -7190.1668 | J26: =I26+J25 -> -6451.3175 | K26: =J26+K25 -> -5476.3937 | ... T26: =S26+T25 -> 11566.433
B27: BE flag | C27: =IF(C26>0,1,"") | D27: =IF(D26>0,2,"") | E27: =IF(E26>0,3,"") | F27: =IF(F26>0,4,"") | G27: =IF(G26>0,5,"") | H27: =IF(H26>0,6,"") | I27: =IF(I26>0,7,"") | J27: =IF(J26>0,8,"") | K27: =IF(K26>0,9,"") | L27: =IF(L26>0,10,"") | M27: =IF(M26>0,11,"") | N27: =IF(N26>0,12,"") | O27: =IF(O26>0,13,"") -> 13 | P27: =IF(P26>0,14,"") -> 14 | Q27: =IF(Q26>0,15,"") -> 15 | R27: =IF(R26>0,16,"") -> 16 | S27: =IF(S26>0,17,"") -> 17 | T27: =IF(T26>0,18,"") -> 18
B31: BASE — 5 partners/mo
B32: New partners/month | C32: 5
B34: Active partners | C34: 0 | D34: 0 | E34: 0 | F34: 0 | G34: =Assumptions!$C$78 -> 7 | H34: =G34+$C$32 -> 12 | I34: =H34+$C$32 -> 17 | J34: =I34+$C$32 -> 22 | K34: =J34+$C$32 -> 27 | L34: =K34+$C$32 -> 32 | M34: =L34+$C$32 -> 37 | N34: =M34+$C$32 -> 42 | O34: =N34+$C$32 -> 47 | ... T34: =S34+$C$32 -> 72
B35: Gross signups | C35: 0 | D35: 0 | E35: 0 | F35: 0 | G35: =ROUND(G34*Assumptions!$C$80*Assumptions!$C$81,0)+ROUND(Assumptions!$C$70/Assumptions!$C$14,0) -> 36 | H35: =ROUND(H34*Assumptions!$C$80*Assumptions!$C$81,0)+ROUND(Assumptions!$C$70/Assumptions!$C$14,0) -> 43 | I35: =ROUND(I34*Assumptions!$C$80*Assumptions!$C$81,0)+ROUND(Assumptions!$C$70/Assumptions!$C$14,0) -> 51 | J35: =ROUND(J34*Assumptions!$C$80*Assumptions!$C$81,0)+ROUND(Assumptions!$C$70/Assumptions!$C$14,0) -> 58 | K35: =ROUND(K34*Assumptions!$C$80*Assumptions!$C$81,0)+ROUND(Assumptions!$C$70/Assumptions!$C$14,0) -> 66 | L35: =ROUND(L34*Assumptions!$C$80*Assumptions!$C$81,0)+ROUND(Assumptions!$C$70/Assumptions!$C$14,0) -> 73 | M35: =ROUND(M34*Assumptions!$C$80*Assumptions!$C$81,0)+ROUND(Assumptions!$C$70/Assumptions!$C$14,0) -> 81 | N35: =ROUND(N34*Assumptions!$C$80*Assumptions!$C$81,0)+ROUND(Assumptions!$C$70/Assumptions!$C$14,0) -> 88 | ... T35: =ROUND(T34*Assumptions!$C$80*Assumptions!$C$81,0)+ROUND(Assumptions!$C$70/Assumptions!$C$14,0) -> 133
B36: Net signups | C36: 0 | D36: 0 | E36: 0 | F36: 0 | G36: =G35-ROUND(G35*Assumptions!$C$6,0) -> 32 | H36: =H35-ROUND(H35*Assumptions!$C$6,0) -> 39 | I36: =I35-ROUND(I35*Assumptions!$C$6,0) -> 46 | J36: =J35-ROUND(J35*Assumptions!$C$6,0) -> 52 | K36: =K35-ROUND(K35*Assumptions!$C$6,0) -> 59 | L36: =L35-ROUND(L35*Assumptions!$C$6,0) -> 66 | M36: =M35-ROUND(M35*Assumptions!$C$6,0) -> 73 | N36: =N35-ROUND(N35*Assumptions!$C$6,0) -> 79 | ... T36: =T35-ROUND(T35*Assumptions!$C$6,0) -> 120
B37: Cumulative users | C37: =C36 -> 0 | D37: =C37+D36 -> 0 | E37: =D37+E36 -> 0 | F37: =E37+F36 -> 0 | G37: =F37+G36 -> 32 | H37: =G37+H36 -> 71 | I37: =H37+I36 -> 117 | J37: =I37+J36 -> 169 | K37: =J37+K36 -> 228 | ... T37: =S37+T36 -> 1064
B38: Net revenue | C38: 0 | D38: 0 | E38: 0 | F38: 0 | G38: =(G36*Assumptions!$C$4)-((G35*Assumptions!$C$4*Assumptions!$C$10)+(G35*Assumptions!$C$11)) -> 1506.044 | H38: =(H36*Assumptions!$C$4)-((H35*Assumptions!$C$4*Assumptions!$C$10)+(H35*Assumptions!$C$11)) -> 1836.997 | I38: =(I36*Assumptions!$C$4)-((I35*Assumptions!$C$4*Assumptions!$C$10)+(I35*Assumptions!$C$11)) -> 2166.229 | J38: =(J36*Assumptions!$C$4)-((J35*Assumptions!$C$4*Assumptions!$C$10)+(J35*Assumptions!$C$11)) -> 2448.182 | K38: =(K36*Assumptions!$C$4)-((K35*Assumptions!$C$4*Assumptions!$C$10)+(K35*Assumptions!$C$11)) -> 2777.414 | L38: =(L36*Assumptions!$C$4)-((L35*Assumptions!$C$4*Assumptions!$C$10)+(L35*Assumptions!$C$11)) -> 3108.367 | M38: =(M36*Assumptions!$C$4)-((M35*Assumptions!$C$4*Assumptions!$C$10)+(M35*Assumptions!$C$11)) -> 3437.599 | N38: =(N36*Assumptions!$C$4)-((N35*Assumptions!$C$4*Assumptions!$C$10)+(N35*Assumptions!$C$11)) -> 3719.552 | ... T38: =(T36*Assumptions!$C$4)-((T35*Assumptions!$C$4*Assumptions!$C$10)+(T35*Assumptions!$C$11)) -> 5651.107
B39: Total COGS | C39: =(COGS!C8+COGS!C9+COGS!C10)+(COGS!$I$4*C36) -> 10 | D39: =(COGS!D8+COGS!D9+COGS!D10)+(COGS!$I$4*D36) -> 10 | E39: =(COGS!E8+COGS!E9+COGS!E10)+(COGS!$I$4*E36) -> 10 | F39: =(COGS!F8+COGS!F9+COGS!F10)+(COGS!$I$4*F36) -> 10 | G39: =(COGS!G8+COGS!G9+COGS!G10)+(COGS!$I$4*G36) -> 37.052096 | H39: =(COGS!H8+COGS!H9+COGS!H10)+(COGS!$I$4*H36) -> 37.500992 | I39: =(COGS!I8+COGS!I9+COGS!I10)+(COGS!$I$4*I36) -> 37.949888 | J39: =(COGS!J8+COGS!J9+COGS!J10)+(COGS!$I$4*J36) -> 38.334656 | ... T39: =(COGS!T8+COGS!T9+COGS!T10)+(COGS!$I$4*T36) -> 42.69536
B40: Gross profit | C40: =C38-C39 -> -10 | D40: =D38-D39 -> -10 | E40: =E38-E39 -> -10 | F40: =F38-F39 -> -10 | G40: =G38-G39 -> 1468.9919 | H40: =H38-H39 -> 1799.496 | I40: =I38-I39 -> 2128.2791 | J40: =J38-J39 -> 2409.8473 | ... T40: =T38-T39 -> 5608.4116
B41: Total OpEx | C41: =OpEx!C25 -> 2888 | D41: =OpEx!D25 -> 1783 | E41: =OpEx!E25 -> 1783 | F41: =OpEx!F25 -> 1783 | G41: =OpEx!G25 -> 1295 | H41: =OpEx!H25 -> 1295 | I41: =OpEx!I25 -> 1295 | J41: =OpEx!J25 -> 1295 | ... T41: =OpEx!T25 -> 1295
B42: EBITDA | C42: =C40-C41 -> -2898 | D42: =D40-D41 -> -1793 | E42: =E40-E41 -> -1793 | F42: =F40-F41 -> -1793 | G42: =G40-G41 -> 173.9919 | H42: =H40-H41 -> 504.49601 | I42: =I40-I41 -> 833.27911 | J42: =J40-J41 -> 1114.8473 | ... T42: =T40-T41 -> 4313.4116
B43: Cumulative cash | C43: =C42 -> -2898 | D43: =C43+D42 -> -4691 | E43: =D43+E42 -> -6484 | F43: =E43+F42 -> -8277 | G43: =F43+G42 -> -8103.0081 | H43: =G43+H42 -> -7598.5121 | I43: =H43+I42 -> -6765.233 | J43: =I43+J42 -> -5650.3856 | K43: =J43+K42 -> -4206.7552 | ... T43: =S43+T42 -> 23134.825
B44: BE flag | C44: =IF(C43>0,1,"") | D44: =IF(D43>0,2,"") | E44: =IF(E43>0,3,"") | F44: =IF(F43>0,4,"") | G44: =IF(G43>0,5,"") | H44: =IF(H43>0,6,"") | I44: =IF(I43>0,7,"") | J44: =IF(J43>0,8,"") | K44: =IF(K43>0,9,"") | L44: =IF(L43>0,10,"") | M44: =IF(M43>0,11,"") | N44: =IF(N43>0,12,"") -> 12 | O44: =IF(O43>0,13,"") -> 13 | P44: =IF(P43>0,14,"") -> 14 | Q44: =IF(Q43>0,15,"") -> 15 | R44: =IF(R43>0,16,"") -> 16 | S44: =IF(S43>0,17,"") -> 17 | T44: =IF(T43>0,18,"") -> 18
B48: AGGRESSIVE — 8 partners/mo
B49: New partners/month | C49: 8
B51: Active partners | C51: 0 | D51: 0 | E51: 0 | F51: 0 | G51: =Assumptions!$C$78 -> 7 | H51: =G51+$C$49 -> 15 | I51: =H51+$C$49 -> 23 | J51: =I51+$C$49 -> 31 | K51: =J51+$C$49 -> 39 | L51: =K51+$C$49 -> 47 | M51: =L51+$C$49 -> 55 | N51: =M51+$C$49 -> 63 | O51: =N51+$C$49 -> 71 | ... T51: =S51+$C$49 -> 111
B52: Gross signups | C52: 0 | D52: 0 | E52: 0 | F52: 0 | G52: =ROUND(G51*Assumptions!$C$80*Assumptions!$C$81,0)+ROUND(Assumptions!$C$70/Assumptions!$C$14,0) -> 36 | H52: =ROUND(H51*Assumptions!$C$80*Assumptions!$C$81,0)+ROUND(Assumptions!$C$70/Assumptions!$C$14,0) -> 48 | I52: =ROUND(I51*Assumptions!$C$80*Assumptions!$C$81,0)+ROUND(Assumptions!$C$70/Assumptions!$C$14,0) -> 60 | J52: =ROUND(J51*Assumptions!$C$80*Assumptions!$C$81,0)+ROUND(Assumptions!$C$70/Assumptions!$C$14,0) -> 72 | K52: =ROUND(K51*Assumptions!$C$80*Assumptions!$C$81,0)+ROUND(Assumptions!$C$70/Assumptions!$C$14,0) -> 84 | L52: =ROUND(L51*Assumptions!$C$80*Assumptions!$C$81,0)+ROUND(Assumptions!$C$70/Assumptions!$C$14,0) -> 96 | M52: =ROUND(M51*Assumptions!$C$80*Assumptions!$C$81,0)+ROUND(Assumptions!$C$70/Assumptions!$C$14,0) -> 108 | N52: =ROUND(N51*Assumptions!$C$80*Assumptions!$C$81,0)+ROUND(Assumptions!$C$70/Assumptions!$C$14,0) -> 120 | ... T52: =ROUND(T51*Assumptions!$C$80*Assumptions!$C$81,0)+ROUND(Assumptions!$C$70/Assumptions!$C$14,0) -> 192
B53: Net signups | C53: 0 | D53: 0 | E53: 0 | F53: 0 | G53: =G52-ROUND(G52*Assumptions!$C$6,0) -> 32 | H53: =H52-ROUND(H52*Assumptions!$C$6,0) -> 43 | I53: =I52-ROUND(I52*Assumptions!$C$6,0) -> 54 | J53: =J52-ROUND(J52*Assumptions!$C$6,0) -> 65 | K53: =K52-ROUND(K52*Assumptions!$C$6,0) -> 76 | L53: =L52-ROUND(L52*Assumptions!$C$6,0) -> 86 | M53: =M52-ROUND(M52*Assumptions!$C$6,0) -> 97 | N53: =N52-ROUND(N52*Assumptions!$C$6,0) -> 108 | ... T53: =T52-ROUND(T52*Assumptions!$C$6,0) -> 173
B54: Cumulative users | C54: =C53 -> 0 | D54: =C54+D53 -> 0 | E54: =D54+E53 -> 0 | F54: =E54+F53 -> 0 | G54: =F54+G53 -> 32 | H54: =G54+H53 -> 75 | I54: =H54+I53 -> 129 | J54: =I54+J53 -> 194 | K54: =J54+K53 -> 270 | ... T54: =S54+T53 -> 1436
...

Sheet TAM
B1: LATCHED — US TAM & PENETRATION STRESS TEST
B2: Top-down market sizing vs. financial-model scenarios · sources cited inline
B4: MARKET FUNNEL (annual, US)
B5: US births / year | C5: 3628934 | E5: CDC/NCHS, Births in the US 2024 (final): 3,628,934
B6: Breastfeeding initiation rate | C6: 0.83 | E6: CDC NIS-Child, birth yr 2022 — 'ever breastfed' ~83% (natl blend of 82.4%–92.2% subgroups)
B7: Breastfeeding mothers / yr (TAM pop.) | C7: =C5*C6 -> 3012015.2 | E7: Serviceable clinical population
B8: Digital-reachable share (smartphone/app) | C8: 0.9 | E8: Assumption — near-universal smartphone use among new mothers; validate
B9: Willing-to-pay for paid lactation app | C9: 0.3 | E9: ASSUMPTION — ties to WTP study (Missing Inputs #10); placeholder 30%
B10: SAM population / yr | C10: =C7*C8*C9 -> 813244.11 | E10: Digital + willing-to-pay narrowing
B11: One-time price ($) | C11: =Assumptions!$C$4 -> 49 | E11: Link → Assumptions
B12: TAM ($ / yr) | C12: =C7*C11 -> 1.4758875e+08 | E12: Breastfeeding mothers × price
B13: SAM ($ / yr) | C13: =C10*C11 -> 39848961 | E13: SAM pop × price
B16: SCENARIO PENETRATION (from financial model)
B17: Scenario | C17: Cum users M18 | D17: Signups M18/mo | E17: Annual run-rate (M18×12) | F17: % of TAM pop (cum) | G17: % of SAM pop (cum) | H17: % of TAM pop (annual run-rate)
B18: Conservative | C18: =Scenarios!F8 -> 818 | D18: =Scenarios!D8 -> 94 | E18: =Scenarios!D8*12 -> 1128 | F18: =C18/$C$7 -> 0.00027157897 | G18: =C18/$C$10 -> 0.001005848 | H18: =E18/$C$7 -> 0.0003745001
B19: Base | C19: =Scenarios!F9 -> 1064 | D19: =Scenarios!D9 -> 133 | E19: =Scenarios!D9*12 -> 1596 | F19: =C19/$C$7 -> 0.00035325187 | G19: =C19/$C$10 -> 0.0013083402 | H19: =E19/$C$7 -> 0.0005298778
B20: Aggressive | C20: =Scenarios!F10 -> 1436 | D20: =Scenarios!D10 -> 192 | E20: =Scenarios!D10*12 -> 2304 | F20: =C20/$C$7 -> 0.00047675722 | G20: =C20/$C$10 -> 0.0017657675 | H20: =E20/$C$7 -> 0.00076493637

Sheet Payer Model
B1: LATCHED — PAYER / SPONSORED SCENARIO (ALTERNATIVE MODEL)
B2: SELF-CONTAINED — does not feed the B2C/referral model.
B3: SCOPE: 12-month journey (milk → solids), one purchase per birth. NOT a subscription.
B4: KEY DISTINCTION: the MEMBER is one-time (a birth doesn't renew). The CONTRACT is recurring (sponsor has a new birth cohort every year).
B6: A. MEMBER ECONOMICS — ONE-TIME PER BIRTH (non-recurring)
B7: Consumer price — hybrid subsidy ($) | C7: 25 | D7: Target palatable price
B8: Sponsor subsidy per member ($) | C8: 24 | D8: Balance of list price
B9: Blended realized price ($) | C9: =C7+C8 -> 49 | D9: Equals list price at parity
B10: Consumer CAC when fully sponsored ($) | C10: 0 | D10: Sponsor IS the distribution → CAC ≈ 0
B11: Member LTV — sponsored (one-time) | C11: =C9*(1-Assumptions!$C$6) -> 44.1 | D11: NO renewal. Journey ends at ~12 months.
B13: B. CONTRACT ECONOMICS — RECURRING (annual birth cohort renews)
B14: Covered births per contract / year | C14: 800 | D14: Sponsor's annual birth cohort — refreshes every year
B15: Engagement / activation rate | C15: 0.45 | D15: Share of cohort that activates
B16: Platform fee per contract / year ($) | C16: 25000 | D16: Maven benchmark: $20–40K
B17: Contract annual renewal rate | C17: 0.85 | D17: Enterprise SaaS-typical
B18: Expected contract life | C18: =1/(1-C17) -> 6.6666667 | D18: Computed as 1/(1-renewal rate)
B19: Contracts signed — Year 1 | C19: 2 | D19: GROWTH LEVER
B21: C. SPONSOR FEE PER COVERED BIRTH — RANGE
B22: Maven benchmark: $700–950 per enrolled member/yr. Latched is a focused point-solution → priced well below.
B23: Fee per birth | C23: Engaged members/contract | D23: Per-member rev/contract | E23: Contract ARR (annual, recurring) | F23: Contract LTV (ARR × life) | G23: Year-1 revenue (all contracts) | H23: % of Maven low end ($700)
B24: 120 | C24: =ROUND($C$14*$C$15,0) -> 360 | D24: =B24*C24 -> 43200 | E24: =D24+$C$16 -> 68200 | F24: =E24*$C$18 -> 454666.67 | G24: =E24*$C$19 -> 136400 | H24: =B24/700 -> 0.17142857
B25: 200 | C25: =ROUND($C$14*$C$15,0) -> 360 | D25: =B25*C25 -> 72000 | E25: =D25+$C$16 -> 97000 | F25: =E25*$C$18 -> 646666.67 | G25: =E25*$C$19 -> 194000 | H25: =B25/700 -> 0.28571429
B26: 300 | C26: =ROUND($C$14*$C$15,0) -> 360 | D26: =B26*C26 -> 108000 | E26: =D26+$C$16 -> 133000 | F26: =E26*$C$18 -> 886666.67 | G26: =E26*$C$19 -> 266000 | H26: =B26/700 -> 0.42857143
B28: D. ROUTE COMPARISON — MEMBER-LEVEL UNIT ECONOMICS (one-time)
B29: Route | C29: Consumer pays | D29: Sponsor pays | E29: Net rev / member | F29: CAC | G29: LTV:CAC | H29: Recurring? | I29: Notes
B30: B2C control ($49 one-time) | C30: =Assumptions!$C$4 -> 49 | D30: 0 | E30: =Assumptions!$C$4*(1-Assumptions!$C$6) -> 44.1 | F30: =Assumptions!$C$14 -> 30 | G30: =IF(F30=0,"n/a (CAC=0)",E30/F30) -> 1.47 | H30: No — member one-time | I30: Current model. Thin economics.
B31: Hybrid subsidy | C31: =C7 -> 25 | D31: =C8 -> 24 | E31: =C11 -> 44.1 | F31: =Assumptions!$C$14*0.5 -> 15 | G31: =IF(F31=0,"n/a (CAC=0)",E31/F31) -> 2.94 | H31: No — member one-time | I31: Bridge. Halves CAC, ~2x LTV:CAC.
B32: Employer sponsored (per birth) | C32: 0 | D32: =B24 -> 120 | E32: =B24*(1-Assumptions!$C$6) -> 108 | F32: =C10 -> 0 | G32: =IF(F32=0,"n/a (CAC=0)",E32/F32) -> n/a (CAC=0) | H32: CONTRACT recurs annually | I32: CAC→0. Contract renews on new cohort.
B33: Health plan / MCO (per birth) | C33: 0 | D33: =B24 -> 120 | E33: =B24*(1-Assumptions!$C$6) -> 108 | F33: =C10 -> 0 | G33: =IF(F33=0,"n/a (CAC=0)",E33/F33) -> n/a (CAC=0) | H33: CONTRACT recurs annually | I33: Largest scale, 12–18mo cycle.
B35: E. WHAT ONE CONTRACT IS WORTH (vs. IBCLC referral engine)
B36: Engaged members — Year 1 (all contracts) | C36: =ROUND(C14*C15*C19,0) -> 720
B37: Equivalent IBCLC partners needed | C37: =ROUND(C36/(Assumptions!$C$80*Assumptions!$C$81*12),0) -> 40 | D37: to match, over a year
B38: Months of partner-onboarding replaced | C38: =ROUND(C37/Assumptions!$C$79,0) -> 8 | D38: at base 5 partners/mo

Sheet Unit Economics
B1: UNIT ECONOMICS
C2: Value | D2: Alt/Range | E2: Notes
B4: REVENUE PER USER
B5: Gross price per user | C5: =Assumptions!$C$4 -> 49 | E5: Source: PRD v0.9 / mvp-experience-spec
B6: Stripe fee per transaction | C6: =(Assumptions!$C$4*Assumptions!$C$10)+Assumptions!$C$11 -> 1.721 | E6: 2.9% × $49 + $0.30 = ~$1.72
B7: Net revenue per user (after Stripe) | C7: =Assumptions!$C$4-(Assumptions!$C$4*Assumptions!$C$10+Assumptions!$C$11) -> 47.279 | E7: ~$47.28 per paid user
B9: COST PER USER (VARIABLE)
B10: LLM cost per user (15-month journey) | C10: =IFERROR((Assumptions!$C$30*Assumptions!$C$31)*((Assumptions!$C$34/1000*Assumptions!$C$32)+(Assumptions!$C$35/1000*Assumptions!$C$33)+(Assumptions!$C$37/1000000*Assumptions!$C$36)),"Fill FAQ query inputs") -> 0.064128 | E10: Requires: queries/user/week in Assumptions
B12: GROSS MARGIN PER USER
B13: Gross margin per user | C13: =IFERROR(C7-C10,"Fill inputs") -> 47.214872
B14: Gross margin % per user | C14: =IFERROR(C13/C7,"-") -> 0.99864363
B16: CUSTOMER ACQUISITION COST (CAC)
B17: B2C CAC — target/base ($) | C17: =Assumptions!$C$14 -> 30 | E17: Source: PRD v0.9 — target <$30; Meta benchmark $30-80
B18: B2C CAC — high scenario ($) | C18: =IFERROR(Assumptions!$C$15,"?") -> 65 | E18: Fill in Assumptions sheet — conservative scenario
B19: B2B2C CAC — estimated ($) | C19: =IFERROR(Assumptions!$C$16,"?") -> 10 | E19: Fill in: printing + outreach + IBCLC onboarding cost per referred user
B20: Blended CAC (40% B2B2C / 60% B2C) | C20: =IFERROR(Assumptions!$C$7*C19+(1-Assumptions!$C$7)*C17,"?") -> 22 | E20: Fill B2B2C CAC to unlock this. B2C CAC = $30 base.
B22: LTV & PAYBACK
B23: LTV (one-time; no expansion revenue in v1) | C23: =C7 -> 47.279 | E23: LTV = net revenue per user. One-time purchase, no upsell in v1.
B24: LTV:CAC (B2C base case) | C24: =IFERROR(C23/C17,"-") -> 1.5759667 | E24: Target >3x for sustainable paid acquisition
B25: Payback period — B2C (months) | C25: =IFERROR(C17/C7,"-") -> 0.63453119 | E25: One-time purchase: payback is instant if CAC < net revenue/user
B27: PRICE SENSITIVITY — 12-MONTH SCOPE
B28: One-time purchase per birth, 15-month journey. NOT a subscription — no renewal within a journey.
